Workbook

Sheet Dashboard
A1: Support Ticket Report — Dashboard
A4: Total Tickets | C4: Open Now | E4: Resolved / Closed | G4: Avg Hours to Resolve | I4: Data-Quality Issues
A5: 3,000 | C5: 465 | E5: 2,535 | G5: 47.3 | I5: 77

Sheet Raw Data (SQL export)
A1: TicketID | B1: CustomerID | C1: CategoryID | D1: AssignedAgentID | E1: Subject | F1: Priority | G1: Status | H1: CreatedAt | I1: ResolvedAt
A2: 1 | B2: 11 | C2: 1 | D2: 2 | E2: Historic orders disappeared from view | F2: Low | G2: Resolved | H2: 2026-06-25 06:55:00 | I2: 2026-06-30 11:41:52
A3: 2 | B3: 2 | C3: 5 | D3: 2 | E3: How do I add a new user? | F3: Medium | G3: Open | H3: 2025-09-09 06:23:00
A4: 3 | B4: 9 | C4: 2 | D4: 5 | E4: Search timing out during peak hours | F4: Low | G4: Closed | H4: 2025-09-11 00:22:00 | I4: 2025-09-17 02:55:54
A5: 4 | B5: 12 | C5: 4 | D5: 2 | E5: Need monthly sales report by region | F5: Medium | G5: Closed | H5: 2025-11-07 17:42:00 | I5: 2025-11-08 19:15:41
A6: 5 | B6: 6 | C6: 3 | D6: 6 | E6: Error 500 when saving a new order | F6: Medium | G6: Resolved | H6: 2026-01-01 21:10:00 | I6: 2026-01-02 07:54:16
A7: 6 | B7: 9 | C7: 3 | D7: 6 | E7: Error 500 when saving a new order | F7: High | G7: Closed | H7: 2025-10-23 03:59:00 | I7: 2025-10-23 20:11:32
A8: 7 | B8: 14 | C8: 2 | D8: 4 | E8: Search timing out during peak hours | F8: Medium | G8: Closed | H8: 2026-04-30 22:53:00 | I8: 2026-05-02 02:25:17
A9: 8 | B9: 11 | C9: 3 | D9: 2 | E9: Export button does nothing | F9: Medium | G9: Resolved | H9: 2026-05-22 12:10:00 | I9: 2026-05-23 07:18:12
A10: 9 | B10: 15 | C10: 5 | D10: 1 | E10: How to schedule an automatic export? | F10: Low | G10: Resolved | H10: 2026-02-03 13:57:00 | I10: 2026-02-03 23:12:51
A11: 10 | B11: 2 | C11: 2 | D11: 4 | E11: Report export extremely slow | F11: Low | G11: Closed | H11: 2025-11-26 08:37:00 | I11: 2025-12-02 18:36:08
A12: 11 | B12: 3 | C12: 2 | D12: 4 | E12: Search timing out during peak hours | F12: Medium | G12: Resolved | H12: 2026-01-03 04:16:00 | I12: 2026-01-04 10:13:28
A13: 12 | B13: 9 | C13: 4 | D13: 1 | E13: Quarterly summary for board pack | F13: Low | G13: Resolved | H13: 2026-05-08 07:15:00 | I13: 2026-05-09 13:29:13
A14: 13 | B14: 2 | C14: 4 | D14: 4 | E14: Need monthly sales report by region | F14: Medium | G14: Closed | H14: 2025-10-08 14:44:00 | I14: 2025-10-11 12:42:31
A15: 14 | B15: 11 | C15: 1 | D15: 3 | E15: Missing records in nightly sync | F15: High | G15: Resolved | H15: 2025-12-31 04:54:00 | I15: 2025-12-31 15:53:58
... A21: 20 | B21: 8 | C21: 1 | D21: 3 | E21: Import file rejected duplicate rows | F21: High | G21: Closed | H21: 2026-01-13 23:33:00 | I21: 2026-01-14 13:17:24
A22: 21 | B22: 2 | C22: 1 | D22: 3 | E22: Customer totals do not match invoice | F22: High | G22: Open | H22: 2026-01-27 18:58:00
A23: 22 | B23: 5 | C23: 4 | D23: 6 | E23: Add discount column to invoice report | F23: Medium | G23: Closed | H23: 2026-02-07 11:57:00 | I23: 2026-02-09 05:55:22
A24: 23 | B24: 13 | C24: 4 | D24: 3 | E24: Add discount column to invoice report | F24: Low | G24: In Progress | H24: 2026-02-24 20:21:00
A25: 24 | B25: 14 | C25: 1 | E25: Import file rejected duplicate rows | F25: Medium | G25: Open | H25: 2026-05-02 20:02:00
A26: 25 | B26: 4 | C26: 2 | D26: 2 | E26: Dashboard takes over a minute to load | F26: Low | G26: Closed | H26: 2026-02-24 23:52:00 | I26: 2026-02-27 01:32:53
A27: 26 | B27: 8 | C27: 5 | E27: How do I add a new user? | F27: Medium | G27: Open | H27: 2026-05-03 04:56:00
A28: 27 | B28: 15 | C28: 2 | D28: 4 | E28: System freezes when opening large accounts | F28: Low | G28: Closed | H28: 2026-03-14 09:31:00 | I28: 2026-03-17 07:17:14
A29: 28 | B29: 1 | C29: 4 | D29: 4 | E29: Quarterly summary for board pack | F29: Low | G29: Resolved | H29: 2026-01-01 09:15:00 | I29: 2026-01-06 07:29:27
A30: 29 | B30: 11 | C30: 4 | D30: 2 | E30: New KPI dashboard for finance team | F30: Medium | G30: Closed | H30: 2026-03-22 18:44:00 | I30: 2026-03-24 13:16:33
A31: 30 | B31: 1 | C31: 1 | D31: 5 | E31: Customer totals do not match invoice | F31: Low | G31: Closed | H31: 2025-07-31 07:32:00 | I31: 2025-08-07 01:06:03
A32: 31 | B32: 2 | C32: 5 | D32: 2 | E32: Can we bulk update product prices? | F32: Low | G32: Resolved | H32: 2026-05-25 00:18:00 | I32: 2026-05-31 14:43:18
A33: 32 | B33: 10 | C33: 1 | D33: 5 | E33: Missing records in nightly sync | F33: Medium | G33: Closed | H33: 2026-05-14 19:15:00 | I33: 2026-05-15 19:23:45
A34: 33 | B34: 4 | C34: 3 | D34: 4 | E34: Error 500 when saving a new order | F34: Low | G34: In Progress | H34: 2025-09-28 07:09:00
A35: 34 | B35: 1 | C35: 4 | D35: 3 | E35: New KPI dashboard for finance team | F35: High | G35: Open | H35: 2026-05-01 16:43:00
A36: 35 | B36: 15 | C36: 1 | D36: 2 | E36: Historic orders disappeared from view | F36: Low | G36: Closed | H36: 2026-01-16 14:50:00 | I36: 2026-01-20 11:55:15
A37: 36 | B37: 1 | C37: 5 | D37: 1 | E37: How do I add a new user? | F37: Medium | G37: Resolved | H37: 2025-12-07 11:59:00 | I37: 2025-12-07 23:23:01
A38: 37 | B38: 12 | C38: 5 | D38: 5 | E38: How to schedule an automatic export? | F38: Low | G38: Closed | H38: 2026-03-22 07:22:00 | I38: 2026-03-24 19:35:56
A39: 38 | B39: 9 | C39: 4 | D39: 1 | E39: Need monthly sales report by region | F39: High | G39: Resolved | H39: 2026-01-11 15:21:00 | I39: 2026-01-12 02:05:32
A40: 39 | B40: 6 | C40: 2 | D40: 4 | E40: Dashboard takes over a minute to load | F40: Medium | G40: Closed | H40: 2026-01-03 18:00:00
A41: 40 | B41: 15 | C41: 2 | D41: 5 | E41: Report export extremely slow | F41: Medium | G41: Resolved | H41: 2026-06-17 06:22:00 | I41: 2026-06-18 14:27:06
A42: 41 | B42: 15 | C42: 1 | D42: 2 | E42: Address data showing in wrong fields | F42: Medium | G42: Closed | H42: 2025-10-25 22:50:00 | I42: 2025-10-27 01:35:27
A43: 42 | B43: 10 | C43: 2 | D43: 2 | E43: Report export extremely slow | F43: Medium | G43: Resolved | H43: 2026-01-22 02:43:00 | I43: 2026-01-22 06:27:06
A44: 43 | B44: 13 | C44: 4 | D44: 6 | E44: Request custom stock level extract | F44: High | G44: Closed | H44: 2026-01-13 18:58:00 | I44: 2026-01-14 16:01:35
A45: 44 | B45: 4 | C45: 4 | D45: 2 | E45: New KPI dashboard for finance team | F45: Low | G45: Closed | H45: 2025-10-31 21:17:00 | I45: 2025-11-05 13:31:43
...

Sheet Cleaned Data
A1: TicketID | B1: Customer | C1: Tier | D1: Region | E1: Category | F1: Agent | G1: Team | H1: Priority | I1: Status | J1: CreatedDate | K1: Month | L1: ResolvedDate | M1: HoursToResolve | N1: IsResolved | O1: DataQualityFlag
A2: 1 | B2: Kite Energy | C2: Business | D2: UK & Ireland | E2: Data Issue | F2: James Whitfield | G2: Technical Services | H2: Low | I2: Resolved | J2: 46198.288 | K2: 2026-06 | L2: 46203.487 | M2: 124.8 | N2: 1
A3: 2 | B3: Bristol Logistics | C3: Business | D3: UK & Ireland | E3: How-To Question | F3: James Whitfield | G3: Technical Services | H3: Medium | I3: Open | J3: 45909.266 | K3: 2025-09 | N3: 0 | O3: Open > 30 days
A4: 3 | B4: Iris Insurance | C4: Business | D4: EMEA | E4: Performance | F4: Sofia Lindqvist | G4: Service Desk | H4: Low | I4: Closed | J4: 45911.015 | K4: 2025-09 | L4: 45917.122 | M4: 146.6 | N4: 1
A5: 4 | B5: Lumen Schools | C5: Standard | D5: UK & Ireland | E5: Report Request | F5: James Whitfield | G5: Technical Services | H5: Medium | I5: Closed | J5: 45968.738 | K5: 2025-11 | L5: 45969.803 | M5: 25.6 | N5: 1
A6: 5 | B6: Fjord Systems | C6: Standard | D6: EMEA | E6: Bug | F6: Dev Patel | G6: Service Desk | H6: Medium | I6: Resolved | J6: 46023.882 | K6: 2026-01 | L6: 46024.329 | M6: 10.7 | N6: 1
A7: 6 | B7: Iris Insurance | C7: Business | D7: EMEA | E7: Bug | F7: Dev Patel | G7: Service Desk | H7: High | I7: Closed | J7: 45953.166 | K7: 2025-10 | L7: 45953.841 | M7: 16.2 | N7: 1
A8: 7 | B8: Nordic Freight | C8: Standard | D8: EMEA | E8: Performance | F8: Marcus Boateng | G8: Service Desk | H8: Medium | I8: Closed | J8: 46142.953 | K8: 2026-04 | L8: 46144.101 | M8: 27.5 | N8: 1
A9: 8 | B9: Kite Energy | C9: Business | D9: UK & Ireland | E9: Bug | F9: James Whitfield | G9: Technical Services | H9: Medium | I9: Resolved | J9: 46164.507 | K9: 2026-05 | L9: 46165.304 | M9: 19.1 | N9: 1
A10: 9 | B10: Orchard Pharma | C10: Business | D10: North America | E10: How-To Question | F10: Priya Sharma | G10: Technical Services | H10: Low | I10: Resolved | J10: 46056.581 | K10: 2026-02 | L10: 46056.967 | M10: 9.3 | N10: 1
A11: 10 | B11: Bristol Logistics | C11: Business | D11: UK & Ireland | E11: Performance | F11: Marcus Boateng | G11: Service Desk | H11: Low | I11: Closed | J11: 45987.359 | K11: 2025-11 | L11: 45993.775 | M11: 154 | N11: 1
A12: 11 | B12: Cornwall Foods | C12: Standard | D12: UK & Ireland | E12: Performance | F12: Marcus Boateng | G12: Service Desk | H12: Medium | I12: Resolved | J12: 46025.178 | K12: 2026-01 | L12: 46026.426 | M12: 30 | N12: 1
A13: 12 | B13: Iris Insurance | C13: Business | D13: EMEA | E13: Report Request | F13: Priya Sharma | G13: Technical Services | H13: Low | I13: Resolved | J13: 46150.302 | K13: 2026-05 | L13: 46151.562 | M13: 30.2 | N13: 1
A14: 13 | B14: Bristol Logistics | C14: Business | D14: UK & Ireland | E14: Report Request | F14: Marcus Boateng | G14: Service Desk | H14: Medium | I14: Closed | J14: 45938.614 | K14: 2025-10 | L14: 45941.53 | M14: 70 | N14: 1
A15: 14 | B15: Kite Energy | C15: Business | D15: UK & Ireland | E15: Data Issue | F15: Elena Kovacs | G15: Service Desk | H15: High | I15: Resolved | J15: 46022.204 | K15: 2025-12 | L15: 46022.662 | M15: 11 | N15: 1
... A21: 20 | B21: Harbour Hotels | C21: Standard | D21: UK & Ireland | E21: Data Issue | F21: Elena Kovacs | G21: Service Desk | H21: High | I21: Closed | J21: 46035.981 | K21: 2026-01 | L21: 46036.554 | M21: 13.7 | N21: 1
A22: 21 | B22: Bristol Logistics | C22: Business | D22: UK & Ireland | E22: Data Issue | F22: Elena Kovacs | G22: Service Desk | H22: High | I22: Open | J22: 46049.79 | K22: 2026-01 | N22: 0 | O22: Open > 30 days
A23: 22 | B23: Everton Health | C23: Enterprise | D23: UK & Ireland | E23: Report Request | F23: Dev Patel | G23: Service Desk | H23: Medium | I23: Closed | J23: 46060.498 | K23: 2026-02 | L23: 46062.247 | M23: 42 | N23: 1
A24: 23 | B24: Metro Transport | C24: Enterprise | D24: EMEA | E24: Report Request | F24: Elena Kovacs | G24: Service Desk | H24: Low | I24: In Progress | J24: 46077.848 | K24: 2026-02 | N24: 0
A25: 24 | B25: Nordic Freight | C25: Standard | D25: EMEA | E25: Data Issue | F25: Unassigned | G25: Unassigned | H25: Medium | I25: Open | J25: 46144.835 | K25: 2026-05 | N25: 0 | O25: Open > 30 days
A26: 25 | B26: DataFirst GmbH | C26: Business | D26: EMEA | E26: Performance | F26: James Whitfield | G26: Technical Services | H26: Low | I26: Closed | J26: 46077.994 | K26: 2026-02 | L26: 46080.065 | M26: 49.7 | N26: 1
A27: 26 | B27: Harbour Hotels | C27: Standard | D27: UK & Ireland | E27: How-To Question | F27: Unassigned | G27: Unassigned | H27: Medium | I27: Open | J27: 46145.206 | K27: 2026-05 | N27: 0 | O27: Open > 30 days
A28: 27 | B28: Orchard Pharma | C28: Business | D28: North America | E28: Performance | F28: Marcus Boateng | G28: Service Desk | H28: Low | I28: Closed | J28: 46095.397 | K28: 2026-03 | L28: 46098.304 | M28: 69.8 | N28: 1
A29: 28 | B29: Acme Retail | C29: Enterprise | D29: UK & Ireland | E29: Report Request | F29: Marcus Boateng | G29: Service Desk | H29: Low | I29: Resolved | J29: 46023.385 | K29: 2026-01 | L29: 46028.312 | M29: 118.2 | N29: 1
A30: 29 | B30: Kite Energy | C30: Business | D30: UK & Ireland | E30: Report Request | F30: James Whitfield | G30: Technical Services | H30: Medium | I30: Closed | J30: 46103.781 | K30: 2026-03 | L30: 46105.553 | M30: 42.5 | N30: 1
A31: 30 | B31: Acme Retail | C31: Enterprise | D31: UK & Ireland | E31: Data Issue | F31: Sofia Lindqvist | G31: Service Desk | H31: Low | I31: Closed | J31: 45869.314 | K31: 2025-07 | L31: 45876.046 | M31: 161.6 | N31: 1
A32: 31 | B32: Bristol Logistics | C32: Business | D32: UK & Ireland | E32: How-To Question | F32: James Whitfield | G32: Technical Services | H32: Low | I32: Resolved | J32: 46167.012 | K32: 2026-05 | L32: 46173.613 | M32: 158.4 | N32: 1
A33: 32 | B33: Juno Media | C33: Standard | D33: North America | E33: Data Issue | F33: Sofia Lindqvist | G33: Service Desk | H33: Medium | I33: Closed | J33: 46156.802 | K33: 2026-05 | L33: 46157.808 | M33: 24.1 | N33: 1
A34: 33 | B34: DataFirst GmbH | C34: Business | D34: EMEA | E34: Bug | F34: Marcus Boateng | G34: Service Desk | H34: Low | I34: In Progress | J34: 45928.298 | K34: 2025-09 | N34: 0
A35: 34 | B35: Acme Retail | C35: Enterprise | D35: UK & Ireland | E35: Report Request | F35: Elena Kovacs | G35: Service Desk | H35: High | I35: Open | J35: 46143.697 | K35: 2026-05 | N35: 0 | O35: Open > 30 days
A36: 35 | B36: Orchard Pharma | C36: Business | D36: North America | E36: Data Issue | F36: James Whitfield | G36: Technical Services | H36: Low | I36: Closed | J36: 46038.618 | K36: 2026-01 | L36: 46042.497 | M36: 93.1 | N36: 1
A37: 36 | B37: Acme Retail | C37: Enterprise | D37: UK & Ireland | E37: How-To Question | F37: Priya Sharma | G37: Technical Services | H37: Medium | I37: Resolved | J37: 45998.499 | K37: 2025-12 | L37: 45998.974 | M37: 11.4 | N37: 1
A38: 37 | B38: Lumen Schools | C38: Standard | D38: UK & Ireland | E38: How-To Question | F38: Sofia Lindqvist | G38: Service Desk | H38: Low | I38: Closed | J38: 46103.307 | K38: 2026-03 | L38: 46105.817 | M38: 60.2 | N38: 1
A39: 38 | B39: Iris Insurance | C39: Business | D39: EMEA | E39: Report Request | F39: Priya Sharma | G39: Technical Services | H39: High | I39: Resolved | J39: 46033.64 | K39: 2026-01 | L39: 46034.087 | M39: 10.7 | N39: 1
A40: 39 | B40: Fjord Systems | C40: Standard | D40: EMEA | E40: Performance | F40: Marcus Boateng | G40: Service Desk | H40: Medium | I40: Closed | J40: 46025.75 | K40: 2026-01 | N40: 1 | O40: Resolved but no ResolvedAt
A41: 40 | B41: Orchard Pharma | C41: Business | D41: North America | E41: Performance | F41: Sofia Lindqvist | G41: Service Desk | H41: Medium | I41: Resolved | J41: 46190.265 | K41: 2026-06 | L41: 46191.602 | M41: 32.1 | N41: 1
A42: 41 | B42: Orchard Pharma | C42: Business | D42: North America | E42: Data Issue | F42: James Whitfield | G42: Technical Services | H42: Medium | I42: Closed | J42: 45955.951 | K42: 2025-10 | L42: 45957.066 | M42: 26.8 | N42: 1
A43: 42 | B43: Juno Media | C43: Standard | D43: North America | E43: Performance | F43: James Whitfield | G43: Technical Services | H43: Medium | I43: Resolved | J43: 46044.113 | K43: 2026-01 | L43: 46044.269 | M43: 3.7 | N43: 1
A44: 43 | B44: Metro Transport | C44: Enterprise | D44: EMEA | E44: Report Request | F44: Dev Patel | G44: Service Desk | H44: High | I44: Closed | J44: 46035.79 | K44: 2026-01 | L44: 46036.668 | M44: 21.1 | N44: 1
A45: 44 | B45: DataFirst GmbH | C45: Business | D45: EMEA | E45: Report Request | F45: James Whitfield | G45: Technical Services | H45: Low | I45: Closed | J45: 45961.887 | K45: 2025-10 | L45: 45966.564 | M45: 112.2 | N45: 1
...

Sheet PivotSummary
A1: Pivot Summaries (built from Cleaned Data)
A4: Tickets by Status | D4: Avg Resolution Time by Priority | G4: Monthly Ticket Trend
A5: Status | B5: Tickets | D5: Priority | E5: Avg Hours to Resolve | G5: Month | H5: Tickets
A6: Open | B6: =COUNTIF('Cleaned Data'!$I$2:$I$3001,A6) -> 228 | D6: High | E6: =IFERROR(ROUND(AVERAGEIFS('Cleaned Data'!$M$2:$M$3001,'Cleaned Data'!$H$2:$H$3001,D6),1),0) -> 12.6 | G6: 2025-07 | H6: =COUNTIF('Cleaned Data'!$K$2:$K$3001,G6) -> 154
A7: In Progress | B7: =COUNTIF('Cleaned Data'!$I$2:$I$3001,A7) -> 237 | D7: Medium | E7: =IFERROR(ROUND(AVERAGEIFS('Cleaned Data'!$M$2:$M$3001,'Cleaned Data'!$H$2:$H$3001,D7),1),0) -> 37.3 | G7: 2025-08 | H7: =COUNTIF('Cleaned Data'!$K$2:$K$3001,G7) -> 241
A8: Resolved | B8: =COUNTIF('Cleaned Data'!$I$2:$I$3001,A8) -> 1196 | D8: Low | E8: =IFERROR(ROUND(AVERAGEIFS('Cleaned Data'!$M$2:$M$3001,'Cleaned Data'!$H$2:$H$3001,D8),1),0) -> 82.8 | G8: 2025-09 | H8: =COUNTIF('Cleaned Data'!$K$2:$K$3001,G8) -> 245
A9: Closed | B9: =COUNTIF('Cleaned Data'!$I$2:$I$3001,A9) -> 1339 | G9: 2025-10 | H9: =COUNTIF('Cleaned Data'!$K$2:$K$3001,G9) -> 247
A10: Total | B10: =SUM(B6:B9) -> 3000 | D10: Tickets by Customer Tier | G10: 2025-11 | H10: =COUNTIF('Cleaned Data'!$K$2:$K$3001,G10) -> 259
D11: Tier | E11: Tickets | G11: 2025-12 | H11: =COUNTIF('Cleaned Data'!$K$2:$K$3001,G11) -> 252
A12: Tickets by Category | D12: Standard | E12: =COUNTIF('Cleaned Data'!$C$2:$C$3001,D12) -> 1212 | G12: 2026-01 | H12: =COUNTIF('Cleaned Data'!$K$2:$K$3001,G12) -> 251
A13: Category | B13: Tickets | D13: Business | E13: =COUNTIF('Cleaned Data'!$C$2:$C$3001,D13) -> 965 | G13: 2026-02 | H13: =COUNTIF('Cleaned Data'!$K$2:$K$3001,G13) -> 211
A14: How-To Question | B14: =COUNTIF('Cleaned Data'!$E$2:$E$3001,A14) -> 637 | D14: Enterprise | E14: =COUNTIF('Cleaned Data'!$C$2:$C$3001,D14) -> 823 | G14: 2026-03 | H14: =COUNTIF('Cleaned Data'!$K$2:$K$3001,G14) -> 255
A15: Report Request | B15: =COUNTIF('Cleaned Data'!$E$2:$E$3001,A15) -> 628 | G15: 2026-04 | H15: =COUNTIF('Cleaned Data'!$K$2:$K$3001,G15) -> 271
A16: Performance | B16: =COUNTIF('Cleaned Data'!$E$2:$E$3001,A16) -> 584 | G16: 2026-05 | H16: =COUNTIF('Cleaned Data'!$K$2:$K$3001,G16) -> 260
A17: Data Issue | B17: =COUNTIF('Cleaned Data'!$E$2:$E$3001,A17) -> 582 | G17: 2026-06 | H17: =COUNTIF('Cleaned Data'!$K$2:$K$3001,G17) -> 258
A18: Bug | B18: =COUNTIF('Cleaned Data'!$E$2:$E$3001,A18) -> 569 | G18: 2026-07 | H18: =COUNTIF('Cleaned Data'!$K$2:$K$3001,G18) -> 96
A19: Total | B19: =SUM(B14:B18) -> 3000

Sheet Notes
A1: Notes
A4: 1. DATA SOURCE
A5: Extracted from SQL Server database 'TicketTracker' (dbo.Tickets, dbo.Customers,
A6: dbo.Agents, dbo.Categories). Raw export is on the 'Raw Data (SQL export)' tab.
A8: 2. CLEANING & TRANSFORMATION (‘Cleaned Data’ tab)
A9: • Joined the lookup tables so IDs became readable names (Customer, Agent, Category).
A10: • Converted CreatedAt / ResolvedAt from text to real dates.
A11: • Added helper columns: Month, HoursToResolve, IsResolved.
A12: • Added a DataQualityFlag column that highlights rows breaking business rules
A13: (resolved with no resolved date; in-progress with no agent; open > 30 days).
A14: • Unassigned agents relabelled 'Unassigned' instead of blank.
A16: 3. REPORTING
... A27: Prepared as a portfolio piece to demonstrate the SQL→Excel reporting workflow.
